<?xml version="1.0"?>
<robot xmlns:xacro="http://ros.org/wiki/xacro">

  <!-- <xacro:include filename="$(find urcell_descriptions)/urdf/parts/fixedparts/fixedobjects.gazebo.xacro"/> -->
  
  <xacro:macro name="custom_gripper" params="parent *joint_origin">
    <joint name="gripper_joint" type="fixed">
        <xacro:insert_block name="joint_origin"/>        
        <parent link="${parent}"/>
        <child link="gripper_base_link" />
    </joint>  

    <link name="gripper_base_link">
        <visual>
            <!--gripper_base-->
            <geometry>
                <mesh filename="file://$(find urcell_description)/meshes/gripper2_gripper_base.dae"/>
            </geometry>
        </visual>
        <collision>
            <!--gripper_base-->
            <geometry>
                <mesh filename="file://$(find urcell_description)/meshes/gripper2_gripper_base.dae"/>
            </geometry>
        </collision>
    </link>
    <link name="finger_link">
        <visual>
            <!--finger-->
            <origin rpy="0.0 -0.0 0.0" xyz="0.0 0.0 0.0"/>
            <geometry>
                <mesh filename="file://$(find urcell_description)/meshes/gripper2_finger.dae"/>
            </geometry>
        </visual>
        <collision>
            <!--finger-->
            <origin rpy="0.0 -0.0 0.0" xyz="0.0 0.0 0.0"/>
            <geometry>
                <mesh filename="file://$(find urcell_description)/meshes/gripper2_finger.dae"/>
            </geometry>
        </collision>
        <inertial>
            <origin xyz="0.0 0.0 0.0" rpy="0.0 0.0 0.0"/>
            <mass value="1.0"/>
            <inertia ixx="0.000225" ixy="0.0" ixz="0.0" iyy="0.000225" iyz="0.0" izz="0.0001"/>
        </inertial>
        <!-- <xacro:box_inertial x="0.03" y="0.03" z="0.1" mass="1" /> Quizas haya que ponerle los datos de inercia pero sin utilizar la macro esta para que agarre correctamente los objetos -->
    </link>
    <joint name="finger_joint" type="prismatic">
        <parent link="gripper_base_link"/>
        <child link="finger_link"/>
        <origin rpy="0.0 0.0 0.0" xyz="0.07 -0.002 0.0578"/>
        <axis xyz="0 0 1"/>
        <limit effort="1000.0" lower="-0.08" upper="0.0" velocity="10.0"/>
    </joint>
  </xacro:macro>  
</robot>
